Workbook

Sheet Допущения
A1: VitaStore — TCO: допущения расчёта
A2: Конкретных затрат в кейсе нет — все значения ниже рыночные оценки. Синие ячейки — входные данные: их можно менять, вся модель пересчитается. Жёлтая заливка — ключевые допущения, сильнее всего влияющие на результат.
A4: Параметр | B4: Значение | C4: Ед. | D4: Источник / обоснование
A5: Масштаб и принцип распределения
A6: Магазинов в расчёте | B6: 100 | C6: шт. | D6: Условие Task 4
A7: Магазинов в сети всего | B7: 500 | C7: шт. | D7: Кейс: «500 собственных магазинов»
A8: Доля расчётного контура в сети | B8: =B6/B7 -> 0.2 | C8: доля | D8: Все общесетевые затраты и эффекты (центральная команда, облачная платформа, внедрение, поток M&A) распределяются на 100 магазинов пропорционально
A9: Касс на магазин | B9: 2 | C9: шт. | D9: Оценка для формата дрогери
A10: ФОТ ИТ-специалиста с налогами | B10: 150000 | C10: ₽/мес | D10: Оценка полной стоимости сотрудника поддержки в РФ; одна ставка для всех ролей
A11: AS-IS: локальный сервер в каждом магазине
A12: Локальный сервер (замена) | B12: 100000 | C12: ₽/шт | D12: Оценка: сервер + ОС для магазина
A13: Срок службы сервера | B13: 5 | C13: лет | D13: Парк в эксплуатации давно — в среднем 1/5 парка меняется ежегодно (ср. INC-8433)
A14: Рабочее место кассы: ПК + фискальный регистратор | B14: 85000 | C14: ₽/касса | D14: Оценка: ПК кассы ~50 тыс. + ФР ~35 тыс.
A15: Срок службы рабочего места кассы | B15: 5 | C15: лет | D15: Оценка
A16: Лицензии и поддержка ПО (Windows Server, SQL, кассовое ПО) | B16: 40000 | C16: ₽/магазин/год | D16: Кейс: «платные лицензии на ПО (Windows Server, SQL)»; оценка
A17: Основной канал связи | B17: 3000 | C17: ₽/магазин/мес | D17: Оценка: бизнес-интернет
A18: Выездов на инциденты | B18: 6 | C18: в год на магазин | D18: Оценка: сервер, ПК, переустановка ПО (ср. INC-8433, выезд 4–6 ч)
A19: Прямые расходы на выезд (транспорт, командировочные) | B19: 5000 | C19: ₽/выезд | D19: Оценка; зарплата инженеров учтена отдельно в ФОТ
A20: TO-BE: смарт-терминалы + облако
A21: Смарт-терминал (Android POS + ФН + принтер) | B21: 50000 | C21: ₽/касса | D21: Оценка по классу устройств (АТОЛ Sigma, Дримкас и аналоги) с фискальным накопителем
A22: Подменный фонд терминалов | B22: 0.05 | C22: доля парка | D22: Для замены курьером вместо выезда инженера (plug-and-play)
A23: Роутер с резервным LTE | B23: 15000 | C23: ₽/магазин | D23: Оценка; нужен для офлайн-стратегии (Task 3)
A24: Комплектов ТСД для онбординга на сеть | B24: 4 | C24: шт. | D24: Многоразовые: курьер забирает комплект после сканирования и везёт в следующий магазин
A25: ТСД в комплекте | B25: 3 | C25: шт. | D25: Оценка для магазина дрогери
A26: Стоимость одного ТСД | B26: 40000 | C26: ₽/шт | D26: Оценка; покупка в Году 1, распределяется по доле контура
A27: Замена вышедших из строя терминалов (Год 2–3) | B27: 0.05 | C27: доля парка в год | D27: Парк новый; плановая замена терминалов по сроку службы в горизонт 3 лет не попадает
A28: Cloud POS SaaS (включая драйверный слой HAL) | B28: 2500 | C28: ₽/касса/мес | D28: Оценка рыночных тарифов кассового SaaS для розницы
A29: Управление устройствами (MDM) | B29: 300 | C29: ₽/устройство/мес | D29: Оценка
A30: Резервный LTE-канал | B30: 1000 | C30: ₽/магазин/мес | D30: Оценка
A31: Выездов подрядчика по вызову | B31: 1 | C31: в год на магазин | D31: Сеть, электрика, нестандартные случаи; всё остальное — замена курьером
A32: Стоимость выезда подрядчика | B32: 8000 | C32: ₽/выезд | D32: Оценка
... A38: Страховые взносы к зарплате | B38: 0.3 | C38: доля | D38: Ставка ФОТ выше включает взносы; выходное пособие взносами не облагается, поэтому считается от зарплаты без них
A39: Финансовые параметры
A40: Ставка дисконтирования | B40: 0.18 | C40: в год | D40: Оценка стоимости капитала в РФ; только для NPV
A41: Эффект ускорения онбординга (лист «Онбординг»)
A42: Покупок магазинов в год по сети | B42: 120 | C42: шт./год | D42: Интервью Data Integration: «скупаем по десять магазинов в месяц»
A43: На сколько дней раньше открывается магазин | B43: 12.5 | C43: дней | D43: Виктор: на 10–15 дней раньше (2–3 недели → 5 дней); середина диапазона
A44: Выручка магазина в день | B44: 150000 | C44: ₽/день | D44: Оценка для регионального магазина дрогери; заменить фактом сделок M&A
A45: Валовая маржа | B45: 0.3 | C45: доля | D45: Оценка для дрогери. Пока магазин закрыт, аренда и зарплата всё равно платятся, поэтому упущенная прибыль = упущенная валовая маржа
A46: Прямые затраты на онбординг As-Is | B46: 160000 | C46: ₽/магазин | D46: Выезд ИТ-бригады (2 чел × 3 дня: дорога, проживание, рабочее время) + ручная сверка товароведом и исправление ~15% ошибок
...

Sheet Штат
A1: Штат поддержки магазинов: расчёт по ролям
A2: Команда поддержки центральная и обслуживает всю сеть из 500 магазинов. Считаем её по ролям для сети, а на 100 магазинов расчёта относим долю (20%). «2,1 ставки на 100 магазинов» — это 20% команды примерно из 10 человек, которая обслуживает всю сеть.
A4: Покрытие первой линии
A5: Часы работы магазинов в неделю (7 дней × 14 ч) | B5: 98 | C5: ч/нед
A6: Рабочих часов одного сотрудника в неделю | B6: 40 | C6: ч/нед
A7: Коэффициент на отпуска и больничные | B7: 1.2 | C7: ×
A8: Сотрудников на одно круглонедельное рабочее место | B8: =$B$5/$B$6*$B$7 -> 2.94
A10: Роль | B10: Драйвер нагрузки | C10: Параметр | D10: FTE на сеть (500) | E10: FTE на 100 магазинов | F10: Комментарий
A11: AS-IS
A12: 1-я линия (Service desk) | B12: Рабочих мест одновременно | C12: 2 | D12: =C12*$B$8 -> 5.88 | E12: =D12*Допущения!$B$8 -> 1.176 | F12: Звонки из магазинов 7 дней в неделю
A13: 2-я линия: администраторы локальных серверов | B13: Магазинов на одного администратора | C13: 80 | D13: =Допущения!$B$7/C13 -> 6.25 | E13: =D13*Допущения!$B$8 -> 1.25 | F13: Патчи Windows/SQL, резервные копии, сбои ночного FTP-обмена
A14: Выездные инженеры | B14: Магазинов на одного инженера | C14: 30 | D14: =Допущения!$B$7/C14 -> 16.666667 | E14: =D14*Допущения!$B$8 -> 3.3333333 | F14: Федеральная сеть: число зависит от географии сети и числа инцидентов
A15: Итого | D15: =SUM(D12:D14) -> 28.796667 | E15: =SUM(E12:E14) -> 5.7593333
A17: TO-BE
A18: 1-я линия (Service desk) | B18: Рабочих мест одновременно | C18: 1.5 | D18: =C18*$B$8 -> 4.41 | E18: =D18*Допущения!$B$8 -> 0.882 | F18: Меньше инцидентов: нет серверов и локальных БД
A19: 2-я линия: Cloud POS и оборудование | B19: Сотрудников | C19: 3 | D19: =C19 -> 3 | E19: =D19*Допущения!$B$8 -> 0.6 | F19: Настройки касс, драйверы HAL, ошибки синхронизации, работа с вендором SaaS
A20: Парк устройств и логистика замен | B20: Сотрудников | C20: 1 | D20: =C20 -> 1 | E20: =D20*Допущения!$B$8 -> 0.2 | F20: MDM, подменный фонд, отправка терминала курьером
A21: Эксплуатация облачных сервисов | B21: Сотрудников | C21: 2 | D21: =C21 -> 2 | E21: =D21*Допущения!$B$8 -> 0.4 | F21: Sync/Queue, сервис онбординга, интеграции с SAP
A22: Итого | D22: =SUM(D18:D21) -> 10.41 | E22: =SUM(E18:E21) -> 2.082
A24: Высвобождается на 100 магазинов, FTE | E24: =Штат!$E$15-Штат!$E$22 -> 3.6773333
A25: Выездные инженеры не исчезают полностью: нестандартные выезды переданы подрядчику по вызову (статья «Выезды» в TCO).

Sheet Раскатка
A1: План перевода магазинов в Году 1
A2: Магазин переводится в конце квартала и работает на новой архитектуре со следующего квартала. Пока магазин не переведён, за него продолжают платить по As-Is — это период двойных расходов.
A4: Квартал Года 1 | B4: Доля парка, переведённая к концу квартала | C4: Переведено к концу квартала, шт. | D4: Работает на To-Be в квартале | E4: Работает на As-Is в квартале | F4: Этап
A5: Q1 | B5: 0.1 | C5: =B5*Допущения!$B$6 -> 10 | D5: =0 -> 0 | E5: =Допущения!$B$6-D5 -> 100 | F5: Пилот
A6: Q2 | B6: 0.4 | C6: =B6*Допущения!$B$6 -> 40 | D6: =C5 -> 10 | E6: =Допущения!$B$6-D6 -> 90 | F6: Волна 1
A7: Q3 | B7: 0.7 | C7: =B7*Допущения!$B$6 -> 70 | D7: =C6 -> 40 | E7: =Допущения!$B$6-D7 -> 60 | F7: Волна 2
A8: Q4 | B8: 1 | C8: =B8*Допущения!$B$6 -> 100 | D8: =C7 -> 70 | E8: =Допущения!$B$6-D8 -> 30 | F8: Волна 3 — все магазины
A9: Доля магазино-лет на To-Be в Году 1 | D9: =SUM(D5:D8)/(4*Допущения!$B$6) -> 0.3
A10: Доля магазино-лет на As-Is в Году 1 | D10: =1-D9 -> 0.7
A12: Синие ячейки — план раскатки (пилот + три волны); можно менять.

Sheet TCO
A1: TCO: As-Is vs To-Be, 100 магазинов, 3 года (₽)
A2: Все суммы — на 100 магазинов. Формулы ссылаются на листы «Допущения», «Штат», «Раскатка».
B3: AS-IS | F3: TO-BE
A4: Статья затрат | B4: Год 1 | C4: Год 2 | D4: Год 3 | E4: Итого 3 года | F4: Год 1 | G4: Год 2 | H4: Год 3 | I4: Итого 3 года | J4: Как считается
A5: Оборудование (CapEx) | B5: =(Допущения!$B$12/Допущения!$B$13+Допущения!$B$9*Допущения!$B$14/Допущения!$B$15)*Допущения!$B$6 -> 5400000 | C5: =(Допущения!$B$12/Допущения!$B$13+Допущения!$B$9*Допущения!$B$14/Допущения!$B$15)*Допущения!$B$6 -> 5400000 | D5: =(Допущения!$B$12/Допущения!$B$13+Допущения!$B$9*Допущения!$B$14/Допущения!$B$15)*Допущения!$B$6 -> 5400000 | E5: =SUM(B5:D5) -> 16200000 | F5: =Допущения!$B$6*(Допущения!$B$9*Допущения!$B$21*(1+Допущения!$B$22)+Допущения!$B$23)+Допущения!$B$24*Допущения!$B$25*Допущения!$B$26*Допущения!$B$8+(Допущения!$B$12/Допущения!$B$13+Допущения!$B$9*Допущения!$B$14/Допущения!$B$15)*Допущения!$B$6*Раскатка!$D$10 -> 15876000 | G5: =Допущения!$B$6*Допущения!$B$9*Допущения!$B$21*Допущения!$B$27 -> 500000 | H5: =Допущения!$B$6*Допущения!$B$9*Допущения!$B$21*Допущения!$B$27 -> 500000 | I5: =SUM(F5:H5) -> 16876000 | J5: As-Is: ежегодная замена сервера и рабочих мест касс по сроку службы. To-Be Год 1: смарт-терминалы, подменный фонд, роутеры + замены As-Is, пока магазины не переведены
A6: Лицензии / Подписки (OpEx) | B6: =Допущения!$B$16*Допущения!$B$6 -> 4000000 | C6: =Допущения!$B$16*Допущения!$B$6 -> 4000000 | D6: =Допущения!$B$16*Допущения!$B$6 -> 4000000 | E6: =SUM(B6:D6) -> 12000000 | F6: =Допущения!$B$16*Допущения!$B$6+(Допущения!$B$9*(Допущения!$B$28+Допущения!$B$29)*12)*Допущения!$B$6*Раскатка!$D$9 -> 6016000 | G6: =Допущения!$B$9*(Допущения!$B$28+Допущения!$B$29)*12*Допущения!$B$6 -> 6720000 | H6: =Допущения!$B$9*(Допущения!$B$28+Допущения!$B$29)*12*Допущения!$B$6 -> 6720000 | I6: =SUM(F6:H6) -> 19456000 | J6: To-Be Год 1: лицензии As-Is оплачены за год вперёд + подписки Cloud POS и MDM за время работы на новой архитектуре
A7: Облачная платформа (доля сети) | B7: =0 -> 0 | C7: =0 -> 0 | D7: =0 -> 0 | E7: =SUM(B7:D7) -> 0 | F7: =(Допущения!$B$33+Допущения!$B$34)*12*Допущения!$B$8 -> 840000 | G7: =(Допущения!$B$33+Допущения!$B$34)*12*Допущения!$B$8 -> 840000 | H7: =(Допущения!$B$33+Допущения!$B$34)*12*Допущения!$B$8 -> 840000 | I7: =SUM(F7:H7) -> 2520000 | J7: Sync/Queue, сервис онбординга, НСИ — общесетевые, относим 20%
A8: ФОТ поддержки | B8: =Штат!$E$15*Допущения!$B$10*12 -> 10366800 | C8: =Штат!$E$15*Допущения!$B$10*12 -> 10366800 | D8: =Штат!$E$15*Допущения!$B$10*12 -> 10366800 | E8: =SUM(B8:D8) -> 31100400 | F8: =(Штат!$E$15+Штат!$E$22)*Допущения!$B$10*12 -> 14114400 | G8: =Штат!$E$22*Допущения!$B$10*12 -> 3747600 | H8: =Штат!$E$22*Допущения!$B$10*12 -> 3747600 | I8: =SUM(F8:H8) -> 21609600 | J8: Лист «Штат». Год 1 To-Be: старая команда работает весь год (легаси + раскатка), новая набрана к пилоту
A9: Каналы связи | B9: =Допущения!$B$17*12*Допущения!$B$6 -> 3600000 | C9: =Допущения!$B$17*12*Допущения!$B$6 -> 3600000 | D9: =Допущения!$B$17*12*Допущения!$B$6 -> 3600000 | E9: =SUM(B9:D9) -> 10800000 | F9: =Допущения!$B$17*12*Допущения!$B$6+Допущения!$B$30*12*Допущения!$B$6*Раскатка!$D$9 -> 3960000 | G9: =(Допущения!$B$17+Допущения!$B$30)*12*Допущения!$B$6 -> 4800000 | H9: =(Допущения!$B$17+Допущения!$B$30)*12*Допущения!$B$6 -> 4800000 | I9: =SUM(F9:H9) -> 13560000 | J9: To-Be: + резервный LTE для офлайн-стратегии
A10: Выезды на инциденты | B10: =Допущения!$B$18*Допущения!$B$19*Допущения!$B$6 -> 3000000 | C10: =Допущения!$B$18*Допущения!$B$19*Допущения!$B$6 -> 3000000 | D10: =Допущения!$B$18*Допущения!$B$19*Допущения!$B$6 -> 3000000 | E10: =SUM(B10:D10) -> 9000000 | F10: =Допущения!$B$18*Допущения!$B$19*Допущения!$B$6*Раскатка!$D$10+Допущения!$B$31*Допущения!$B$32*Допущения!$B$6*Раскатка!$D$9 -> 2340000 | G10: =Допущения!$B$31*Допущения!$B$32*Допущения!$B$6 -> 800000 | H10: =Допущения!$B$31*Допущения!$B$32*Допущения!$B$6 -> 800000 | I10: =SUM(F10:H10) -> 3940000 | J10: As-Is: свои инженеры (прямые расходы). To-Be: подрядчик по вызову
A11: Внедрение (разово) | B11: =0 -> 0 | C11: =0 -> 0 | D11: =0 -> 0 | E11: =SUM(B11:D11) -> 0 | F11: =Допущения!$B$35*Допущения!$B$8+Допущения!$B$36*Допущения!$B$6 -> 5000000 | G11: =0 -> 0 | H11: =0 -> 0 | I11: =SUM(F11:H11) -> 5000000 | J11: Доля проекта внедрения + перевод каждого магазина
A12: Сокращение штата (разово) | B12: =0 -> 0 | C12: =0 -> 0 | D12: =0 -> 0 | E12: =SUM(B12:D12) -> 0 | F12: =0 -> 0 | G12: =Штат!$E$24*Допущения!$B$10/(1+Допущения!$B$38)*Допущения!$B$37 -> 848615.38 | H12: =0 -> 0 | I12: =SUM(F12:H12) -> 848615.38 | J12: Выходные пособия высвобождаемым сотрудникам в начале Года 2
A13: ИТОГО TCO | B13: =SUM(B5:B12) -> 26366800 | C13: =SUM(C5:C12) -> 26366800 | D13: =SUM(D5:D12) -> 26366800 | E13: =SUM(E5:E12) -> 79100400 | F13: =SUM(F5:F12) -> 48146400 | G13: =SUM(G5:G12) -> 18256215 | H13: =SUM(H5:H12) -> 17407600 | I13: =SUM(I5:I12) -> 83810215
A15: Экономия To-Be vs As-Is | B15: =B13-F13 -> -21779600 | C15: =C13-G13 -> 8110584.6 | D15: =D13-H13 -> 8959200 | E15: =E13-I13 -> -4709815.4 | F15: ← Год 1 — период раскатки и двойных расходов; Год 3 — установившийся режим
A16: Снижение TCO, % | B16: =IF(B13=0,0,(B13-F13)/B13) -> -0.82602364 | C16: =IF(C13=0,0,(C13-G13)/C13) -> 0.30760595 | D16: =IF(D13=0,0,(D13-H13)/D13) -> 0.33979095 | E16: =IF(E13=0,0,(E13-I13)/E13) -> -0.059542245

Sheet Онбординг
A1: Эффект ускорения онбординга купленных магазинов
A2: Вне TCO: TCO считает содержание уже работающих 100 магазинов. Здесь — выгода от того, что каждый купленный магазин открывается на 10–15 дней раньше и дешевле подключается. Поток покупок распределён на контур по той же доле 20%. Будущая экономия на содержании новых магазинов сознательно не учтена (консервативно).
A4: Показатель | B4: Значение | C4: Как считается
A5: Упущенная валовая маржа, которую сохраняем | B5: =Допущения!$B$43*Допущения!$B$44*Допущения!$B$45*Допущения!$B$48 -> 562500 | C5: дней раньше × выручка в день × валовая маржа (0, если магазин торгует под старой вывеской)
A6: Экономия прямых затрат на онбординг | B6: =Допущения!$B$46-Допущения!$B$47-Допущения!$B$50 -> 120000 | C6: без выезда бригады и ручной сверки; за вычетом стоимости AI-сопоставления
A7: Минус: оборудование для нового магазина | B7: =-(Допущения!$B$9*Допущения!$B$21+Допущения!$B$23) -> -115000 | C7: в As-Is купленный магазин работал на своём старом железе
A8: Чистый эффект на один купленный магазин | B8: =SUM(B5:B7) -> 567500
A9: Покупок в год, отнесённых на контур | B9: =Допущения!$B$42*Допущения!$B$8 -> 24 | C9: 10 в месяц по сети × 20%
A10: Эффект в год (полный год работы процесса) | B10: =B8*B9 -> 13620000
B12: Год 1 | C12: Год 2 | D12: Год 3
A13: Эффект онбординга по годам | B13: =B10*Допущения!$B$49 -> 6810000 | C13: =B10 -> 13620000 | D13: =B10 -> 13620000

Sheet ROI
A1: ROI и срок окупаемости (Break-even)
A3: Показатель | B3: Год 1 | C3: Год 2 | D3: Год 3
A4: Экономия TCO (лист TCO) | B4: =TCO!$B$15 -> -21779600 | C4: =TCO!$C$15 -> 8110584.6 | D4: =TCO!$D$15 -> 8959200
A5: Эффект онбординга (лист «Онбординг») | B5: =Онбординг!$B$13 -> 6810000 | C5: =Онбординг!$C$13 -> 13620000 | D5: =Онбординг!$D$13 -> 13620000
A6: Итого выгода, вариант Б | B6: =B4+B5 -> -14969600 | C6: =C4+C5 -> 21730585 | D6: =D4+D5 -> 22579200
A7: Накопленно — вариант А (только TCO) | B7: =B4 -> -21779600 | C7: =B7+C4 -> -13669015 | D7: =C7+D4 -> -4709815.4
A8: Накопленно — вариант Б (TCO + онбординг) | B8: =B6 -> -14969600 | C8: =B8+C6 -> 6760984.6 | D8: =C8+D6 -> 29340185
A10: Инвестиции (разовые затраты To-Be)
A11: Смарт-терминалы, подменный фонд, роутеры, доля комплектов ТСД | B11: =Допущения!$B$6*(Допущения!$B$9*Допущения!$B$21*(1+Допущения!$B$22)+Допущения!$B$23)+Допущения!$B$24*Допущения!$B$25*Допущения!$B$26*Допущения!$B$8 -> 12096000
A12: Внедрение | B12: =TCO!$F$11 -> 5000000
A13: Двойные расходы Года 1 (ФОТ новой команды при сохранении старой) | B13: =Штат!$E$22*Допущения!$B$10*12 -> 3747600
A14: Выходные пособия | B14: =TCO!$G$12 -> 848615.38
A15: Итого инвестиции | B15: =SUM(B11:B14) -> 21692215
A17: Итог | B17: Вариант А: только TCO | C17: Вариант Б: TCO + онбординг
A18: Экономия / выгода за 3 года, ₽ | B18: =D7 -> -4709815.4 | C18: =D8 -> 29340185
A19: ROI за 3 года = накопленная выгода / инвестиции | B19: =IF(B15=0,0,D7/B15) -> -0.21712007 | C19: =IF(B15=0,0,D8/B15) -> 1.3525675
A20: Срок окупаемости, месяцев от старта проекта | B20: =IF(B7>=0,"до 12",IF(C7>=0,12+12*(-B7)/C4,IF(D7>=0,24+12*(-C7)/D4,IF(D4>0,36+12*(-D7)/D4,"не окупается")))) -> 42.308352 | C20: =IF(B8>=0,"до 12",IF(C8>=0,12+12*(-B8)/C6,IF(D8>=0,24+12*(-C8)/D6,IF(D6>0,36+12*(-D8)/D6,"не окупается")))) -> 20.266469
A21: NPV за 3 года (ставка из «Допущений») | B21: =B4/(1+Допущения!$B$40)+C4/(1+Допущения!$B$40)^2+D4/(1+Допущения!$B$40)^3 -> -7179546.8 | C21: =B6/(1+Допущения!$B$40)+C6/(1+Допущения!$B$40)^2+D6/(1+Допущения!$B$40)^3 -> 16662864
A22: Снижение TCO в установившемся режиме (Год 3) | B22: =TCO!$D$16 -> 0.33979095
A24: Окупаемость считается по годовым суммам с линейным распределением внутри года; если за 3 года не окупается — продлевается с экономией Года 3. Инвестиции входят в TCO To-Be Года 1–2, поэтому накопленная выгода уже чистая.
A26: Целевые показатели кейса (Год 3, установившийся режим) | B26: As-Is | C26: To-Be | D26: Снижение
A27: Цель кейса | D27: 0.4
A28: 1) Затраты на ИТ-поддержку сети = ФОТ поддержки + выезды на инциденты | B28: =TCO!$D$8+TCO!$D$10 -> 13366800 | C28: =TCO!$H$8+TCO!$H$10 -> 4547600 | D28: =IF(B28=0,0,1-C28/B28) -> 0.65978394
A29: 2) Полный TCO магазинов (оборудование, лицензии, связь, облако, поддержка) | B29: =TCO!$D$13 -> 26366800 | C29: =TCO!$H$13 -> 17407600 | D29: =IF(B29=0,0,1-C29/B29) -> 0.33979095
A30: Не хватает до цели по полному TCO, ₽/год (0 — цель достигнута) | C30: =MAX(0,C29-(1-D27)*B29) -> 1587520
A32: Условия, при которых полный TCO снижается на цель (каждое по отдельности):
A33: Цена Cloud POS SaaS не выше, ₽ за кассу в месяц | C33: =Допущения!$B$28-C30/(Допущения!$B$9*12*Допущения!$B$6) -> 1838.5333
A34: То же, если управление устройствами (MDM) входит в подписку Cloud POS | C34: =Допущения!$B$28-MAX(0,C30-Допущения!$B$9*Допущения!$B$29*12*Допущения!$B$6)/(Допущения!$B$9*12*Допущения!$B$6) -> 2138.5333
A35: Штат поддержки To-Be не больше, FTE на 100 магазинов | C35: =Штат!$E$22-C30/(Допущения!$B$10*12) -> 1.2000444
A37: Цель по ИТ-поддержке достигается с запасом: исчезают администраторы локальных серверов и почти все выезды. Цель по полному TCO — это требование к закупке: цена подписки Cloud POS фиксируется в тендере не выше расчётной.

Sheet Чувствительность
A1: Чувствительность результата к ключевым допущениям
A2: Каждая строка меняет одно допущение относительно базы и пересчитывает выгоду по годам. Изменение штата To-Be учитывает и ФОТ, и выходные пособия.
A3: Шаг изменения (синие ячейки можно править):
A4: Штат To-Be, +FTE на 100 магазинов | B4: 1
A5: Цена Cloud POS SaaS, ± | B5: 0.3
A6: Выручка магазина в день, ± | B6: 0.3
A7: Открытие раньше на (альтернатива), дней | B7: 10
A8: Открытие раньше на (альтернатива), дней | B8: 15
A10: Сценарий | B10: TCO Год 1 | C10: TCO Год 2 | D10: TCO Год 3 | E10: Онб. Год 1 | F10: Онб. Год 2 | G10: Онб. Год 3 | H10: Окупаемость А, мес. | I10: Окупаемость Б, мес.
A11: База | B11: =TCO!$B$15+0 -> -21779600 | C11: =TCO!$C$15+0 -> 8110584.6 | D11: =TCO!$D$15+0 -> 8959200 | E11: =Онбординг!$B$13+0 -> 6810000 | F11: =Онбординг!$C$13+0 -> 13620000 | G11: =Онбординг!$D$13+0 -> 13620000 | H11: =IF(B11>=0,"до 12",IF((B11+C11)>=0,12+12*(-B11)/C11,IF((B11+C11+D11)>=0,24+12*(-(B11+C11))/D11,IF(D11>0,36+12*(-(B11+C11+D11))/D11,"не окупается")))) -> 42.308352 | I11: =IF((B11+E11)>=0,"до 12",IF((B11+E11+C11+F11)>=0,12+12*(-(B11+E11))/(C11+F11),IF((B11+E11+C11+F11+D11+G11)>=0,24+12*(-(B11+E11+C11+F11))/(D11+G11),IF((D11+G11)>0,36+12*(-(B11+E11+C11+F11+D11+G11))/(D11+G11),"не окупается")))) -> 20.266469
A12: Штат To-Be больше на шаг | B12: =TCO!$B$15+-$B$4*Допущения!$B$10*12 -> -23579600 | C12: =TCO!$C$15+-$B$4*Допущения!$B$10*12+$B$4*Допущения!$B$10/(1+Допущения!$B$38)*Допущения!$B$37 -> 6541353.8 | D12: =TCO!$D$15+-$B$4*Допущения!$B$10*12 -> 7159200 | E12: =Онбординг!$B$13+0 -> 6810000 | F12: =Онбординг!$C$13+0 -> 13620000 | G12: =Онбординг!$D$13+0 -> 13620000 | H12: =IF(B12>=0,"до 12",IF((B12+C12)>=0,12+12*(-B12)/C12,IF((B12+C12+D12)>=0,24+12*(-(B12+C12))/D12,IF(D12>0,36+12*(-(B12+C12+D12))/D12,"не окупается")))) -> 52.558911 | I12: =IF((B12+E12)>=0,"до 12",IF((B12+E12+C12+F12)>=0,12+12*(-(B12+E12))/(C12+F12),IF((B12+E12+C12+F12+D12+G12)>=0,24+12*(-(B12+E12+C12+F12))/(D12+G12),IF((D12+G12)>0,36+12*(-(B12+E12+C12+F12+D12+G12))/(D12+G12),"не окупается")))) -> 21.981234
A13: SaaS дороже на шаг | B13: =TCO!$B$15+-$B$5*(Допущения!$B$9*Допущения!$B$28*12*Допущения!$B$6*Раскатка!$D$9) -> -22319600 | C13: =TCO!$C$15+-$B$5*(Допущения!$B$9*Допущения!$B$28*12*Допущения!$B$6) -> 6310584.6 | D13: =TCO!$D$15+-$B$5*(Допущения!$B$9*Допущения!$B$28*12*Допущения!$B$6) -> 7159200 | E13: =Онбординг!$B$13+0 -> 6810000 | F13: =Онбординг!$C$13+0 -> 13620000 | G13: =Онбординг!$D$13+0 -> 13620000 | H13: =IF(B13>=0,"до 12",IF((B13+C13)>=0,12+12*(-B13)/C13,IF((B13+C13+D13)>=0,24+12*(-(B13+C13))/D13,IF(D13>0,36+12*(-(B13+C13+D13))/D13,"не окупается")))) -> 50.83375 | I13: =IF((B13+E13)>=0,"до 12",IF((B13+E13+C13+F13)>=0,12+12*(-(B13+E13))/(C13+F13),IF((B13+E13+C13+F13+D13+G13)>=0,24+12*(-(B13+E13+C13+F13))/(D13+G13),IF((D13+G13)>0,36+12*(-(B13+E13+C13+F13+D13+G13))/(D13+G13),"не окупается")))) -> 21.338171
A14: SaaS дешевле на шаг | B14: =TCO!$B$15+$B$5*(Допущения!$B$9*Допущения!$B$28*12*Допущения!$B$6*Раскатка!$D$9) -> -21239600 | C14: =TCO!$C$15+$B$5*(Допущения!$B$9*Допущения!$B$28*12*Допущения!$B$6) -> 9910584.6 | D14: =TCO!$D$15+$B$5*(Допущения!$B$9*Допущения!$B$28*12*Допущения!$B$6) -> 10759200 | E14: =Онбординг!$B$13+0 -> 6810000 | F14: =Онбординг!$C$13+0 -> 13620000 | G14: =Онбординг!$D$13+0 -> 13620000 | H14: =IF(B14>=0,"до 12",IF((B14+C14)>=0,12+12*(-B14)/C14,IF((B14+C14+D14)>=0,24+12*(-(B14+C14))/D14,IF(D14>0,36+12*(-(B14+C14+D14))/D14,"не окупается")))) -> 36.635529 | I14: =IF((B14+E14)>=0,"до 12",IF((B14+E14+C14+F14)>=0,12+12*(-(B14+E14))/(C14+F14),IF((B14+E14+C14+F14+D14+G14)>=0,24+12*(-(B14+E14+C14+F14))/(D14+G14),IF((D14+G14)>0,36+12*(-(B14+E14+C14+F14+D14+G14))/(D14+G14),"не окупается")))) -> 19.358729
A15: Выручка магазина ниже на шаг | B15: =TCO!$B$15+0 -> -21779600 | C15: =TCO!$C$15+0 -> 8110584.6 | D15: =TCO!$D$15+0 -> 8959200 | E15: =Онбординг!$B$13+-$B$6*(Допущения!$B$44*Допущения!$B$45*Допущения!$B$43*Допущения!$B$48)*Онбординг!$B$9*Допущения!$B$49 -> 4785000 | F15: =Онбординг!$C$13+-$B$6*(Допущения!$B$44*Допущения!$B$45*Допущения!$B$43*Допущения!$B$48)*Онбординг!$B$9*1 -> 9570000 | G15: =Онбординг!$D$13+-$B$6*(Допущения!$B$44*Допущения!$B$45*Допущения!$B$43*Допущения!$B$48)*Онбординг!$B$9*1 -> 9570000 | H15: =IF(B15>=0,"до 12",IF((B15+C15)>=0,12+12*(-B15)/C15,IF((B15+C15+D15)>=0,24+12*(-(B15+C15))/D15,IF(D15>0,36+12*(-(B15+C15+D15))/D15,"не окупается")))) -> 42.308352 | I15: =IF((B15+E15)>=0,"до 12",IF((B15+E15+C15+F15)>=0,12+12*(-(B15+E15))/(C15+F15),IF((B15+E15+C15+F15+D15+G15)>=0,24+12*(-(B15+E15+C15+F15))/(D15+G15),IF((D15+G15)>0,36+12*(-(B15+E15+C15+F15+D15+G15))/(D15+G15),"не окупается")))) -> 23.534415
A16: Открытие раньше на 10 дней | B16: =TCO!$B$15+0 -> -21779600 | C16: =TCO!$C$15+0 -> 8110584.6 | D16: =TCO!$D$15+0 -> 8959200 | E16: =Онбординг!$B$13+($B$7-Допущения!$B$43)*Допущения!$B$44*Допущения!$B$45*Допущения!$B$48*Онбординг!$B$9*Допущения!$B$49 -> 5460000 | F16: =Онбординг!$C$13+($B$7-Допущения!$B$43)*Допущения!$B$44*Допущения!$B$45*Допущения!$B$48*Онбординг!$B$9*1 -> 10920000 | G16: =Онбординг!$D$13+($B$7-Допущения!$B$43)*Допущения!$B$44*Допущения!$B$45*Допущения!$B$48*Онбординг!$B$9*1 -> 10920000 | H16: =IF(B16>=0,"до 12",IF((B16+C16)>=0,12+12*(-B16)/C16,IF((B16+C16+D16)>=0,24+12*(-(B16+C16))/D16,IF(D16>0,36+12*(-(B16+C16+D16))/D16,"не окупается")))) -> 42.308352 | I16: =IF((B16+E16)>=0,"до 12",IF((B16+E16+C16+F16)>=0,12+12*(-(B16+E16))/(C16+F16),IF((B16+E16+C16+F16+D16+G16)>=0,24+12*(-(B16+E16+C16+F16))/(D16+G16),IF((D16+G16)>0,36+12*(-(B16+E16+C16+F16+D16+G16))/(D16+G16),"не окупается")))) -> 22.290551
A17: Магазин торгует под старой вывеской | B17: =TCO!$B$15+0 -> -21779600 | C17: =TCO!$C$15+0 -> 8110584.6 | D17: =TCO!$D$15+0 -> 8959200 | E17: =Онбординг!$B$13+-(Допущения!$B$44*Допущения!$B$45*Допущения!$B$43*Допущения!$B$48)*Онбординг!$B$9*Допущения!$B$49 -> 60000 | F17: =Онбординг!$C$13+-(Допущения!$B$44*Допущения!$B$45*Допущения!$B$43*Допущения!$B$48)*Онбординг!$B$9*1 -> 120000 | G17: =Онбординг!$D$13+-(Допущения!$B$44*Допущения!$B$45*Допущения!$B$43*Допущения!$B$48)*Онбординг!$B$9*1 -> 120000 | H17: =IF(B17>=0,"до 12",IF((B17+C17)>=0,12+12*(-B17)/C17,IF((B17+C17+D17)>=0,24+12*(-(B17+C17))/D17,IF(D17>0,36+12*(-(B17+C17+D17))/D17,"не окупается")))) -> 42.308352 | I17: =IF((B17+E17)>=0,"до 12",IF((B17+E17+C17+F17)>=0,12+12*(-(B17+E17))/(C17+F17),IF((B17+E17+C17+F17+D17+G17)>=0,24+12*(-(B17+E17+C17+F17))/(D17+G17),IF((D17+G17)>0,36+12*(-(B17+E17+C17+F17+D17+G17))/(D17+G17),"не окупается")))) -> 41.828463
A18: Открытие раньше на 15 дней | B18: =TCO!$B$15+0 -> -21779600 | C18: =TCO!$C$15+0 -> 8110584.6 | D18: =TCO!$D$15+0 -> 8959200 | E18: =Онбординг!$B$13+($B$8-Допущения!$B$43)*Допущения!$B$44*Допущения!$B$45*Допущения!$B$48*Онбординг!$B$9*Допущения!$B$49 -> 8160000 | F18: =Онбординг!$C$13+($B$8-Допущения!$B$43)*Допущения!$B$44*Допущения!$B$45*Допущения!$B$48*Онбординг!$B$9*1 -> 16320000 | G18: =Онбординг!$D$13+($B$8-Допущения!$B$43)*Допущения!$B$44*Допущения!$B$45*Допущения!$B$48*Онбординг!$B$9*1 -> 16320000 | H18: =IF(B18>=0,"до 12",IF((B18+C18)>=0,12+12*(-B18)/C18,IF((B18+C18+D18)>=0,24+12*(-(B18+C18))/D18,IF(D18>0,36+12*(-(B18+C18+D18))/D18,"не окупается")))) -> 42.308352 | I18: =IF((B18+E18)>=0,"до 12",IF((B18+E18+C18+F18)>=0,12+12*(-(B18+E18))/(C18+F18),IF((B18+E18+C18+F18+D18+G18)>=0,24+12*(-(B18+E18+C18+F18))/(D18+G18),IF((D18+G18)>0,36+12*(-(B18+E18+C18+F18+D18+G18))/(D18+G18),"не окупается")))) -> 18.689779
